  0%|                                                                                                                   | 2/10000 [00:00<1:07:27,  2.47it/s]
Traceback (most recent call last):
  File "/home/shuvrajeet/Documents/GitHub/ReinforcementLearning/DeepRL/CleanRL/DoubleDQN_Discrete.py", line 185, in <module>
    main()
  File "/home/shuvrajeet/Documents/GitHub/ReinforcementLearning/DeepRL/CleanRL/DoubleDQN_Discrete.py", line 181, in main
    agent.train()
  File "/home/shuvrajeet/Documents/GitHub/ReinforcementLearning/DeepRL/CleanRL/DoubleDQN_Discrete.py", line 168, in train
    loss = self.replay()
  File "/home/shuvrajeet/Documents/GitHub/ReinforcementLearning/DeepRL/CleanRL/DoubleDQN_Discrete.py", line 148, in replay
    loss_value = self.train_step(*self.buffer.sample())
  File "/usr/lib/python3.10/site-packages/tensorflow/python/util/traceback_utils.py", line 153, in error_handler
    raise e.with_traceback(filtered_tb) from None
  File "/tmp/__autograph_generated_filexwxvowrs.py", line 12, in tf__train_step
    next_indices = ag__.converted_call(ag__.ld(tf).stack, ([ag__.converted_call(ag__.ld(tf).range, (ag__.ld(args).batch_size,), None, fscope), ag__.converted_call(ag__.ld(tf).argmax, (ag__.converted_call(ag__.ld(self).model.model, (ag__.ld(next_states),), None, fscope),), dict(axis=1, dtype=ag__.ld(tf).int32), fscope)],), dict(axis=1), fscope)
TypeError: in user code:
    File "/home/shuvrajeet/Documents/GitHub/ReinforcementLearning/DeepRL/CleanRL/DoubleDQN_Discrete.py", line 129, in train_step  *
        next_indices = tf.stack([tf.range(
    TypeError: Got an unexpected keyword argument 'dtype'